Workbook

Sheet 차이 금액
B3: =사업장!B4 -> 사업장 | C3: =사업장!C4 -> 사업장명 | D3: =사업장!D4 -> 사업자등록번호 | E3: =사업장!N4 -> 공급가액2 | F3: =사업장!O4 -> 세액2 | G3: =사업장!P4 -> 계산서2 | H3: =사업장!Q4 -> 세금계산서 수기업로드 진행여부 | I3: =사업장!R4 -> 계산서 수기업로드 진행여부
B4: =사업장!B3 -> F100 | C4: =사업장!C3 -> (주)이랜드월드 | D4: =사업장!D3 -> 1058144184 | E4: =사업장!N3 -> 0 | F4: =사업장!O3 -> 0 | G4: =사업장!P3 -> 0 | H4: =사업장!Q3 -> FALSE | I4: =사업장!R3 -> FALSE
B5: =사업장!B5 -> E006 | C5: =사업장!C5 -> 후아유 명동점 | D5: =사업장!D5 -> 2018527593 | E5: =사업장!N5 -> 0 | F5: =사업장!O5 -> 0 | G5: =사업장!P5 -> 0 | H5: =사업장!Q5 -> FALSE | I5: =사업장!R5 -> FALSE
B6: =사업장!B6 -> E026 | C6: =사업장!C6 -> 스파오 동성로중앙 | D6: =사업장!D6 -> 5048535541 | E6: =사업장!N6 -> 0 | F6: =사업장!O6 -> 0 | G6: =사업장!P6 -> 0 | H6: =사업장!Q6 -> FALSE | I6: =사업장!R6 -> FALSE
B7: =사업장!B7 -> E031 | C7: =사업장!C7 -> 이랜드 답십리점 | D7: =사업장!D7 -> 2048523903 | E7: =사업장!N7 -> 0 | F7: =사업장!O7 -> 0 | G7: =사업장!P7 -> 0 | H7: =사업장!Q7 -> FALSE | I7: =사업장!R7 -> FALSE
B8: =사업장!B8 -> E032 | C8: =사업장!C8 -> 이랜드월드 속초지점 | D8: =사업장!D8 -> 2278510245 | E8: =사업장!N8 -> 0 | F8: =사업장!O8 -> 0 | G8: =사업장!P8 -> 0 | H8: =사업장!Q8 -> FALSE | I8: =사업장!R8 -> FALSE
B9: =사업장!B9 -> E033 | C9: =사업장!C9 -> (주)이랜드 목동지점 | D9: =사업장!D9 -> 1178521635 | E9: =사업장!N9 -> 0 | F9: =사업장!O9 -> 0 | G9: =사업장!P9 -> 0 | H9: =사업장!Q9 -> FALSE | I9: =사업장!R9 -> FALSE
B10: =사업장!B10 -> E034 | C10: =사업장!C10 -> 이랜드월드 시흥지점 | D10: =사업장!D10 -> 1198534081 | E10: =사업장!N10 -> 0 | F10: =사업장!O10 -> 0 | G10: =사업장!P10 -> 0 | H10: =사업장!Q10 -> FALSE | I10: =사업장!R10 -> FALSE
B11: =사업장!B11 -> E059 | C11: =사업장!C11 -> (주)이랜드월드 파주첼시점 | D11: =사업장!D11 -> 1418512124 | E11: =사업장!N11 -> 0 | F11: =사업장!O11 -> 0 | G11: =사업장!P11 -> 0 | H11: =사업장!Q11 -> FALSE | I11: =사업장!R11 -> FALSE
B12: =사업장!B12 -> W001 | C12: =사업장!C12 -> (주)이랜드월드패션사업부 | D12: =사업장!D12 -> 1138519030 | E12: =사업장!N12 -> 14803497 | F12: =사업장!O12 -> 1480351 | G12: =사업장!P12 -> 0 | H12: =사업장!Q12 -> TRUE | I12: =사업장!R12 -> FALSE
B13: =사업장!B13 -> W003 | C13: =사업장!C13 -> (주)이랜드월드 에블린 명동점 | D13: =사업장!D13 -> 2018515457 | E13: =사업장!N13 -> 0 | F13: =사업장!O13 -> 0 | G13: =사업장!P13 -> 0 | H13: =사업장!Q13 -> FALSE | I13: =사업장!R13 -> FALSE
B14: =사업장!B14 -> W004 | C14: =사업장!C14 -> 이랜드월드 로엠신촌 | D14: =사업장!D14 -> 1108518051 | E14: =사업장!N14 -> 0 | F14: =사업장!O14 -> 0 | G14: =사업장!P14 -> 0 | H14: =사업장!Q14 -> FALSE | I14: =사업장!R14 -> FALSE
B15: =사업장!B15 -> W006 | C15: =사업장!C15 -> (주)이랜드월드패션투미신촌 | D15: =사업장!D15 -> 1108517839 | E15: =사업장!N15 -> 0 | F15: =사업장!O15 -> 0 | G15: =사업장!P15 -> 0 | H15: =사업장!Q15 -> FALSE | I15: =사업장!R15 -> FALSE
B16: =사업장!B16 -> W008 | C16: =사업장!C16 -> (주)이랜드월드건대스타시티점 | D16: =사업장!D16 -> 2068522797 | E16: =사업장!N16 -> 0 | F16: =사업장!O16 -> 0 | G16: =사업장!P16 -> 0 | H16: =사업장!Q16 -> FALSE | I16: =사업장!R16 -> FALSE
... B183: =사업장!B183 -> W463 | C183: =사업장!C183 -> (주)이랜드월드 진주 | D183: =사업장!D183 -> 2158548957 | E183: =사업장!N183 -> 0 | F183: =사업장!O183 -> 0 | G183: =사업장!P183 -> 0 | H183: =사업장!Q183 -> FALSE | I183: =사업장!R183 -> FALSE

Sheet Sheet1

Sheet 국세청 금액
A1: 사업장 | B1: 공급가액 | C1: 세액 | D1: 계산서
A2: F100 | B2: 4044074516 | C2: 403763747 | D2: 1469257510
A3: E006 | B3: 23236 | C3: 2323
A4: E026 | B4: 197097354 | C4: 19709734 | D4: 2200255
A5: E031
A6: E032 | B6: 1800 | C6: 180
A7: E033 | B7: 675098 | C7: 67510
A8: E034 | B8: 5379143 | C8: 537914
A9: E059 | B9: 56842402 | C9: 5684240
A10: W001 | B10: 53647278952 | C10: 5325305753 | D10: 683444019
A11: W003 | B11: 30507487 | C11: 3050752 | D11: 244000
A12: W004 | B12: 25220022 | C12: 2522001
A13: W006 | B13: 23253591 | C13: 2325358
A14: W008 | B14: 50474384 | C14: 5047439 | D14: 158200
A15: W063 | B15: 16820791 | C15: 1682079
A16: W065 | B16: 15911235 | C16: 1591058 | D16: 5599
A17: W068 | B17: 21836784 | C17: 2183678
A18: W077
A19: W100 | B19: 115668354 | C19: 11566851
A20: W103 | B20: 2499599 | C20: 249959
A21: W130 | B21: 420000 | C21: 42000
A22: W165 | B22: 15022353 | C22: 1502234
A23: W169 | B23: 50540618 | C23: 5054061
A24: W181
A25: W182 | B25: 380545455 | C25: 38054545
A26: W196 | B26: 33332206 | C26: 3333221 | D26: 337892
A27: W202 | B27: 72092543 | C27: 7209254 | D27: 263000
A28: W204 | B28: 61720120 | C28: 6172012 | D28: 18438
A29: W207 | B29: 36493023 | C29: 3649302
A30: W209 | B30: 204020539 | C30: 20402056
A31: W212 | B31: 70797053 | C31: 7079706 | D31: 4181
A32: W220 | B32: 70964411 | C32: 7096437 | D32: 72964
A33: W222 | B33: 152475553 | C33: 15247561
A34: W227 | B34: 36668460 | C34: 3666845
A35: W228 | B35: 83816687 | C35: 8381670
A36: W229 | B36: 439843 | C36: 43984
A37: W232
A38: W233 | B38: 44504700 | C38: 4450472 | D38: 6309
A39: W238 | B39: 16433756 | C39: 1643373 | D39: 104679
A40: W241 | B40: 5910353 | C40: 591035
...

Sheet SAP 금액
A1: 세금계산서 | E1: 계산서
A2: 사업장 | B2: 공급가액 | C2: 세액 | E2: 사업장 | F2: 공급가액
A3: E006 | B3: 23236 | C3: 2323 | E3: E026 | F3: 2200255
A4: E026 | B4: 197097354 | C4: 19709734 | E4: F100 | F4: 1469257510
A5: E032 | B5: 1800 | C5: 180 | E5: W001 | F5: 683444019
A6: E033 | B6: 675098 | C6: 67510 | E6: W003 | F6: 244000
A7: E034 | B7: 5379143 | C7: 537914 | E7: W008 | F7: 158200
A8: E059 | B8: 56842402 | C8: 5684240 | E8: W065 | F8: 5599
A9: F100 | B9: 4044074516 | C9: 403763747 | E9: W196 | F9: 337892
A10: W001 | B10: 53632475455 | C10: 5323825402 | E10: W202 | F10: 263000
A11: W003 | B11: 30507487 | C11: 3050752 | E11: W204 | F11: 18438
A12: W004 | B12: 25220022 | C12: 2522001 | E12: W212 | F12: 4181
A13: W006 | B13: 23253591 | C13: 2325358 | E13: W220 | F13: 72964
A14: W008 | B14: 50474384 | C14: 5047439 | E14: W233 | F14: 6309
... A66: W319 | B66: 110337826 | C66: 11033782 | E66: W462 | F66: 98648
A67: W320 | B67: 22834477 | C67: 2283448
A68: W321 | B68: 241030334 | C68: 24103040
A69: W323 | B69: 141049 | C69: 14104
A70: W330 | B70: 5111168 | C70: 511116
A71: W331 | B71: 10117630 | C71: 1011763
A72: W332 | B72: 138904 | C72: 13890
A73: W333 | B73: 26110962 | C73: 2611096
A74: W336 | B74: 41216229 | C74: 4121623
A75: W338 | B75: 25584737 | C75: 2558473
A76: W341 | B76: 147050521 | C76: 14705038
A77: W345 | B77: 121017 | C77: 12101
A78: W346 | B78: 19063860 | C78: 1906380
... A169: W463 | B169: 332074056 | C169: 33207405

Sheet 사업장
H2: SAP 금액 | K2: 국세청 금액 | N2: 차이 금액
B3: F100 | C3: (주)이랜드월드 | D3: 1058144184 | E3: =LEFT(D3,3) -> 105 | F3: =MID(D3,4,2) -> 81 | G3: =RIGHT(D3,5) -> 44184 | H3: =IFERROR(VLOOKUP($B3,'SAP 금액'!$A:$C,2,0),0) -> 4044074516 | I3: =IFERROR(VLOOKUP($B3,'SAP 금액'!$A:$C,3,0),0) -> 403763747 | J3: =IFERROR(VLOOKUP(B3,'SAP 금액'!E:F,2,0),0) -> 1469257510 | K3: =VLOOKUP($B3,'국세청 금액'!$A:$C,2,0) -> 4044074516 | L3: =VLOOKUP($B3,'국세청 금액'!$A:$C,3,0) -> 403763747 | M3: =VLOOKUP(B3,'국세청 금액'!A:D,4,0) -> 1469257510 | N3: =K3-H3 -> 0 | O3: =L3-I3 -> 0 | P3: =M3-J3 -> 0 | Q3: =AND(N3<>0,O3<>0) -> FALSE | R3: =AND(O3<>0,P3<>0) -> FALSE
B4: 사업장 | C4: 사업장명 | D4: 사업자등록번호 | E4: 앞 | F4: 중간 | G4: 뒤 | H4: 공급가액 | I4: 세액 | J4: 계산서 | K4: 공급가액1 | L4: 세액1 | M4: 계산서1 | N4: 공급가액2 | O4: 세액2 | P4: 계산서2 | Q4: 세금계산서 수기업로드 진행여부 | R4: 계산서 수기업로드 진행여부
B5: E006 | C5: 후아유 명동점 | D5: 2018527593 | E5: =LEFT(D5,3) -> 201 | F5: =MID(D5,4,2) -> 85 | G5: =RIGHT(D5,5) -> 27593 | H5: =IFERROR(VLOOKUP($B5,'SAP 금액'!$A:$C,2,0),0) -> 23236 | I5: =IFERROR(VLOOKUP($B5,'SAP 금액'!$A:$C,3,0),0) -> 2323 | J5: =IFERROR(VLOOKUP(B5,'SAP 금액'!E:F,2,0),0) -> 0 | K5: =VLOOKUP($B5,'국세청 금액'!$A:$C,2,0) -> 23236 | L5: =VLOOKUP($B5,'국세청 금액'!$A:$C,3,0) -> 2323 | M5: =VLOOKUP(B5,'국세청 금액'!A:D,4,0) -> 0 | N5: =K5-H5 -> 0 | O5: =L5-I5 -> 0 | P5: =M5-J5 -> 0 | Q5: =AND(N5<>0,O5<>0) -> FALSE | R5: =P5<>0 -> FALSE
B6: E026 | C6: 스파오 동성로중앙 | D6: 5048535541 | E6: =LEFT(D6,3) -> 504 | F6: =MID(D6,4,2) -> 85 | G6: =RIGHT(D6,5) -> 35541 | H6: =IFERROR(VLOOKUP($B6,'SAP 금액'!$A:$C,2,0),0) -> 197097354 | I6: =IFERROR(VLOOKUP($B6,'SAP 금액'!$A:$C,3,0),0) -> 19709734 | J6: =IFERROR(VLOOKUP(B6,'SAP 금액'!E:F,2,0),0) -> 2200255 | K6: =VLOOKUP($B6,'국세청 금액'!$A:$C,2,0) -> 197097354 | L6: =VLOOKUP($B6,'국세청 금액'!$A:$C,3,0) -> 19709734 | M6: =VLOOKUP(B6,'국세청 금액'!A:D,4,0) -> 2200255 | N6: =K6-H6 -> 0 | O6: =L6-I6 -> 0 | P6: =M6-J6 -> 0 | Q6: =AND(N6<>0,O6<>0) -> FALSE | R6: =P6<>0 -> FALSE
B7: E031 | C7: 이랜드 답십리점 | D7: 2048523903 | E7: =LEFT(D7,3) -> 204 | F7: =MID(D7,4,2) -> 85 | G7: =RIGHT(D7,5) -> 23903 | H7: =IFERROR(VLOOKUP($B7,'SAP 금액'!$A:$C,2,0),0) -> 0 | I7: =IFERROR(VLOOKUP($B7,'SAP 금액'!$A:$C,3,0),0) -> 0 | J7: =IFERROR(VLOOKUP(B7,'SAP 금액'!E:F,2,0),0) -> 0 | K7: =VLOOKUP($B7,'국세청 금액'!$A:$C,2,0) -> 0 | L7: =VLOOKUP($B7,'국세청 금액'!$A:$C,3,0) -> 0 | M7: =VLOOKUP(B7,'국세청 금액'!A:D,4,0) -> 0 | N7: =K7-H7 -> 0 | O7: =L7-I7 -> 0 | P7: =M7-J7 -> 0 | Q7: =AND(N7<>0,O7<>0) -> FALSE | R7: =P7<>0 -> FALSE
B8: E032 | C8: 이랜드월드 속초지점 | D8: 2278510245 | E8: =LEFT(D8,3) -> 227 | F8: =MID(D8,4,2) -> 85 | G8: =RIGHT(D8,5) -> 10245 | H8: =IFERROR(VLOOKUP($B8,'SAP 금액'!$A:$C,2,0),0) -> 1800 | I8: =IFERROR(VLOOKUP($B8,'SAP 금액'!$A:$C,3,0),0) -> 180 | J8: =IFERROR(VLOOKUP(B8,'SAP 금액'!E:F,2,0),0) -> 0 | K8: =VLOOKUP($B8,'국세청 금액'!$A:$C,2,0) -> 1800 | L8: =VLOOKUP($B8,'국세청 금액'!$A:$C,3,0) -> 180 | M8: =VLOOKUP(B8,'국세청 금액'!A:D,4,0) -> 0 | N8: =K8-H8 -> 0 | O8: =L8-I8 -> 0 | P8: =M8-J8 -> 0 | Q8: =AND(N8<>0,O8<>0) -> FALSE | R8: =P8<>0 -> FALSE
B9: E033 | C9: (주)이랜드 목동지점 | D9: 1178521635 | E9: =LEFT(D9,3) -> 117 | F9: =MID(D9,4,2) -> 85 | G9: =RIGHT(D9,5) -> 21635 | H9: =IFERROR(VLOOKUP($B9,'SAP 금액'!$A:$C,2,0),0) -> 675098 | I9: =IFERROR(VLOOKUP($B9,'SAP 금액'!$A:$C,3,0),0) -> 67510 | J9: =IFERROR(VLOOKUP(B9,'SAP 금액'!E:F,2,0),0) -> 0 | K9: =VLOOKUP($B9,'국세청 금액'!$A:$C,2,0) -> 675098 | L9: =VLOOKUP($B9,'국세청 금액'!$A:$C,3,0) -> 67510 | M9: =VLOOKUP(B9,'국세청 금액'!A:D,4,0) -> 0 | N9: =K9-H9 -> 0 | O9: =L9-I9 -> 0 | P9: =M9-J9 -> 0 | Q9: =AND(N9<>0,O9<>0) -> FALSE | R9: =P9<>0 -> FALSE
B10: E034 | C10: 이랜드월드 시흥지점 | D10: 1198534081 | E10: =LEFT(D10,3) -> 119 | F10: =MID(D10,4,2) -> 85 | G10: =RIGHT(D10,5) -> 34081 | H10: =IFERROR(VLOOKUP($B10,'SAP 금액'!$A:$C,2,0),0) -> 5379143 | I10: =IFERROR(VLOOKUP($B10,'SAP 금액'!$A:$C,3,0),0) -> 537914 | J10: =IFERROR(VLOOKUP(B10,'SAP 금액'!E:F,2,0),0) -> 0 | K10: =VLOOKUP($B10,'국세청 금액'!$A:$C,2,0) -> 5379143 | L10: =VLOOKUP($B10,'국세청 금액'!$A:$C,3,0) -> 537914 | M10: =VLOOKUP(B10,'국세청 금액'!A:D,4,0) -> 0 | N10: =K10-H10 -> 0 | O10: =L10-I10 -> 0 | P10: =M10-J10 -> 0 | Q10: =AND(N10<>0,O10<>0) -> FALSE | R10: =P10<>0 -> FALSE
B11: E059 | C11: (주)이랜드월드 파주첼시점 | D11: 1418512124 | E11: =LEFT(D11,3) -> 141 | F11: =MID(D11,4,2) -> 85 | G11: =RIGHT(D11,5) -> 12124 | H11: =IFERROR(VLOOKUP($B11,'SAP 금액'!$A:$C,2,0),0) -> 56842402 | I11: =IFERROR(VLOOKUP($B11,'SAP 금액'!$A:$C,3,0),0) -> 5684240 | J11: =IFERROR(VLOOKUP(B11,'SAP 금액'!E:F,2,0),0) -> 0 | K11: =VLOOKUP($B11,'국세청 금액'!$A:$C,2,0) -> 56842402 | L11: =VLOOKUP($B11,'국세청 금액'!$A:$C,3,0) -> 5684240 | M11: =VLOOKUP(B11,'국세청 금액'!A:D,4,0) -> 0 | N11: =K11-H11 -> 0 | O11: =L11-I11 -> 0 | P11: =M11-J11 -> 0 | Q11: =AND(N11<>0,O11<>0) -> FALSE | R11: =P11<>0 -> FALSE
B12: W001 | C12: (주)이랜드월드패션사업부 | D12: 1138519030 | E12: =LEFT(D12,3) -> 113 | F12: =MID(D12,4,2) -> 85 | G12: =RIGHT(D12,5) -> 19030 | H12: =IFERROR(VLOOKUP($B12,'SAP 금액'!$A:$C,2,0),0) -> 53632475455 | I12: =IFERROR(VLOOKUP($B12,'SAP 금액'!$A:$C,3,0),0) -> 5323825402 | J12: =IFERROR(VLOOKUP(B12,'SAP 금액'!E:F,2,0),0) -> 683444019 | K12: =VLOOKUP($B12,'국세청 금액'!$A:$C,2,0) -> 53647278952 | L12: =VLOOKUP($B12,'국세청 금액'!$A:$C,3,0) -> 5325305753 | M12: =VLOOKUP(B12,'국세청 금액'!A:D,4,0) -> 683444019 | N12: =K12-H12 -> 14803497 | O12: =L12-I12 -> 1480351 | P12: =M12-J12 -> 0 | Q12: =AND(N12<>0,O12<>0) -> TRUE | R12: =P12<>0 -> FALSE
B13: W003 | C13: (주)이랜드월드 에블린 명동점 | D13: 2018515457 | E13: =LEFT(D13,3) -> 201 | F13: =MID(D13,4,2) -> 85 | G13: =RIGHT(D13,5) -> 15457 | H13: =IFERROR(VLOOKUP($B13,'SAP 금액'!$A:$C,2,0),0) -> 30507487 | I13: =IFERROR(VLOOKUP($B13,'SAP 금액'!$A:$C,3,0),0) -> 3050752 | J13: =IFERROR(VLOOKUP(B13,'SAP 금액'!E:F,2,0),0) -> 244000 | K13: =VLOOKUP($B13,'국세청 금액'!$A:$C,2,0) -> 30507487 | L13: =VLOOKUP($B13,'국세청 금액'!$A:$C,3,0) -> 3050752 | M13: =VLOOKUP(B13,'국세청 금액'!A:D,4,0) -> 244000 | N13: =K13-H13 -> 0 | O13: =L13-I13 -> 0 | P13: =M13-J13 -> 0 | Q13: =AND(N13<>0,O13<>0) -> FALSE | R13: =P13<>0 -> FALSE
B14: W004 | C14: 이랜드월드 로엠신촌 | D14: 1108518051 | E14: =LEFT(D14,3) -> 110 | F14: =MID(D14,4,2) -> 85 | G14: =RIGHT(D14,5) -> 18051 | H14: =IFERROR(VLOOKUP($B14,'SAP 금액'!$A:$C,2,0),0) -> 25220022 | I14: =IFERROR(VLOOKUP($B14,'SAP 금액'!$A:$C,3,0),0) -> 2522001 | J14: =IFERROR(VLOOKUP(B14,'SAP 금액'!E:F,2,0),0) -> 0 | K14: =VLOOKUP($B14,'국세청 금액'!$A:$C,2,0) -> 25220022 | L14: =VLOOKUP($B14,'국세청 금액'!$A:$C,3,0) -> 2522001 | M14: =VLOOKUP(B14,'국세청 금액'!A:D,4,0) -> 0 | N14: =K14-H14 -> 0 | O14: =L14-I14 -> 0 | P14: =M14-J14 -> 0 | Q14: =AND(N14<>0,O14<>0) -> FALSE | R14: =P14<>0 -> FALSE
B15: W006 | C15: (주)이랜드월드패션투미신촌 | D15: 1108517839 | E15: =LEFT(D15,3) -> 110 | F15: =MID(D15,4,2) -> 85 | G15: =RIGHT(D15,5) -> 17839 | H15: =IFERROR(VLOOKUP($B15,'SAP 금액'!$A:$C,2,0),0) -> 23253591 | I15: =IFERROR(VLOOKUP($B15,'SAP 금액'!$A:$C,3,0),0) -> 2325358 | J15: =IFERROR(VLOOKUP(B15,'SAP 금액'!E:F,2,0),0) -> 0 | K15: =VLOOKUP($B15,'국세청 금액'!$A:$C,2,0) -> 23253591 | L15: =VLOOKUP($B15,'국세청 금액'!$A:$C,3,0) -> 2325358 | M15: =VLOOKUP(B15,'국세청 금액'!A:D,4,0) -> 0 | N15: =K15-H15 -> 0 | O15: =L15-I15 -> 0 | P15: =M15-J15 -> 0 | Q15: =AND(N15<>0,O15<>0) -> FALSE | R15: =P15<>0 -> FALSE
B16: W008 | C16: (주)이랜드월드건대스타시티점 | D16: 2068522797 | E16: =LEFT(D16,3) -> 206 | F16: =MID(D16,4,2) -> 85 | G16: =RIGHT(D16,5) -> 22797 | H16: =IFERROR(VLOOKUP($B16,'SAP 금액'!$A:$C,2,0),0) -> 50474384 | I16: =IFERROR(VLOOKUP($B16,'SAP 금액'!$A:$C,3,0),0) -> 5047439 | J16: =IFERROR(VLOOKUP(B16,'SAP 금액'!E:F,2,0),0) -> 158200 | K16: =VLOOKUP($B16,'국세청 금액'!$A:$C,2,0) -> 50474384 | L16: =VLOOKUP($B16,'국세청 금액'!$A:$C,3,0) -> 5047439 | M16: =VLOOKUP(B16,'국세청 금액'!A:D,4,0) -> 158200 | N16: =K16-H16 -> 0 | O16: =L16-I16 -> 0 | P16: =M16-J16 -> 0 | Q16: =AND(N16<>0,O16<>0) -> FALSE | R16: =P16<>0 -> FALSE
... B183: W463 | C183: (주)이랜드월드 진주 | D183: 2158548957 | E183: =LEFT(D183,3) -> 215 | F183: =MID(D183,4,2) -> 85 | G183: =RIGHT(D183,5) -> 48957 | H183: =IFERROR(VLOOKUP($B183,'SAP 금액'!$A:$C,2,0),0) -> 332074056 | I183: =IFERROR(VLOOKUP($B183,'SAP 금액'!$A:$C,3,0),0) -> 33207405 | J183: =IFERROR(VLOOKUP(B183,'SAP 금액'!E:F,2,0),0) -> 0 | K183: =VLOOKUP($B183,'국세청 금액'!$A:$C,2,0) -> 332074056 | L183: =VLOOKUP($B183,'국세청 금액'!$A:$C,3,0) -> 33207405 | M183: =VLOOKUP(B183,'국세청 금액'!A:D,4,0) -> 0 | N183: =K183-H183 -> 0 | O183: =L183-I183 -> 0 | P183: =M183-J183 -> 0 | Q183: =AND(N183<>0,O183<>0) -> FALSE | R183: =P183<>0 -> FALSE
